Workbook

Sheet Read me
A1: Breach register template
A2: RiskLens Australia · free template · version 1.0 (September 2026)
A4: What this is | B4: A register for recording breaches and possible breaches of obligations, assessing whether they must be reported, tracking notification deadlines, and following remediation through to closure. Background: https://hayesskvaril-ctrl.github.io/risk-management/incident-and-breach-management.html
A5: How to use it | B5: 1. Log every breach or possible breach as soon as it is identified, including the date the organisation became aware. 2. Assess significance and record your reasoning, especially where you decide a matter is not reportable. 3. For each regulator, record whether a report is needed, the deadline and the date lodged. The ASIC deadline calculates automatically. 4. Track root cause, corrective actions and customer remediation until closure. 5. The 'Dashboard' tab summarises the register for management and board reporting.
A6: ASIC deadline | B6: For ASIC reportable situations, the register calculates 30 calendar days from the 'Date aware' column. That is when the licensee first knew of, or was reckless about, reasonable grounds to believe a reportable situation had arisen. Check RG 78 and any current ASIC relief for your circumstances.
A7: Other deadlines | B7: APRA, OAIC, AUSTRAC and other deadlines vary by regime (from 24 hours to 30 days). Enter those deadline dates yourself. See https://hayesskvaril-ctrl.github.io/compliance/breach-reporting.html
A8: Colour key | B8: Pale yellow cells: fill these in (many have drop-down lists). Grey-blue cells: calculated automatically; don't type over them. Green row: a worked example. Replace or delete it.
A9: Status formulas | B9: Deadline status shows 'Due in X days', 'OVERDUE', 'On time' or 'Late', and uses today's date, so it updates each time the file is opened.
A10: Important | B10: RiskLens Australia provides general educational information only. It is not legal, financial or compliance advice and does not take into account your circumstances. Always refer to the official legislation and regulator guidance, and seek professional advice where appropriate.
A12: Fill in
A13: Calculated
A14: Example

Sheet Lists
A1: Drop-down lists
A2: Edit these values to suit your organisation. The register's drop-downs read from this tab.
A4: Source of obligation | B4: How identified | C4: Yes / No | D4: Remediation status | E4: Breach status
A5: Corporations Act | B5: Control / monitoring | C5: Yes | D5: Not required | E5: Open
A6: SIS Act / Regulations | B6: Complaint | C6: No | D6: Scoping | E6: Under investigation
A7: National Credit Act | B7: Staff report | C7: Under assessment | D7: Calculating | E7: Remediation in progress
A8: ASIC Act | B8: Internal audit | C8: N/A | D8: Paying | E8: Closed
A9: ASIC instrument or RG | B9: External audit | D9: Complete
A10: APRA prudential standard | B10: Service provider
A11: Privacy Act | B11: Regulator
A12: AML/CTF Act | B12: Whistleblower
A13: Industry code | B13: Other
A14: Licence condition
A15: Contract
A16: Internal policy
A17: Other

Sheet Breach register
A1: Breach register
A2: Fill in the pale yellow cells. Deadlines, status and days open calculate automatically.
A4: Breach ID | B4: Date identified | C4: Date aware (clock start) | D4: Description | E4: Business unit | F4: Obligation breached | G4: Source of obligation | H4: How identified | I4: Breach owner | J4: Customers / members affected | K4: Estimated financial impact ($) | L4: Significant? | M4: Significance reasoning | N4: ASIC report required? | O4: ASIC deadline (30 days) | P4: ASIC lodged date | Q4: ASIC status | R4: APRA notification required? | S4: APRA deadline | T4: APRA notified date | U4: APRA status | V4: OAIC data breach? | W4: Other notifications (AUSTRAC, customers, others) | X4: Customer remediation required? | Y4: Remediation status | Z4: Root cause | AA4: Corrective actions | AB4: Action owner | AC4: Action due date | AD4: Breach status | AE4: Date closed | AF4: Days open | AG4: Notes
A5: B-2026-001 | B5: 46266 | C5: 46266 | D5: Administration fee calculated on the wrong basis for about 3,000 members since a product change 18 months ago. | E5: Operations | F5: Charging fees not permitted by the governing rules / PDS; efficiently, honestly and fairly (s 912A) | G5: Corporations Act | H5: Service provider | I5: Head of Operations | J5: 3000 | K5: 450000 | L5: Yes | M5: Likely to cause material loss to members across a large group; treated as deemed significant. | N5: Yes | O5: =IF(AND(N5="Yes",ISNUMBER(C5)),C5+30,"") -> 46296 | P5: 46289 | Q5: =IF(OR(N5<>"Yes",NOT(ISNUMBER(O5))),"",IF(ISNUMBER(P5),IF(P5<=O5,"On time","Late"),IF(TODAY()>O5,"OVERDUE","Due in "&(O5-TODAY())&" days"))) -> On time | R5: Yes | S5: 46296 | T5: 46289 | U5: =IF(OR(R5<>"Yes",NOT(ISNUMBER(S5))),"",IF(ISNUMBER(T5),IF(T5<=S5,"On time","Late"),IF(TODAY()>S5,"OVERDUE","Due in "&(S5-TODAY())&" days"))) -> On time | V5: No | W5: Board Risk Committee informed 10/09/2026 | X5: Yes | Y5: Calculating | Z5: Product change testing did not include fee calculation scenarios. | AA5: Fix calculation; add fee scenarios to change testing; monthly independent fee reconciliation. | AB5: Product Manager | AC5: 46387 | AD5: Remediation in progress | AF5: =IF(ISNUMBER(C5),IF(ISNUMBER(AE5),AE5-C5,TODAY()-C5),"") -> 26 | AG5: One report to APRA containing all ASIC-required information can count as lodgement with ASIC for RSE licensees.
O6: =IF(AND(N6="Yes",ISNUMBER(C6)),C6+30,"") | Q6: =IF(OR(N6<>"Yes",NOT(ISNUMBER(O6))),"",IF(ISNUMBER(P6),IF(P6<=O6,"On time","Late"),IF(TODAY()>O6,"OVERDUE","Due in "&(O6-TODAY())&" days"))) | U6: =IF(OR(R6<>"Yes",NOT(ISNUMBER(S6))),"",IF(ISNUMBER(T6),IF(T6<=S6,"On time","Late"),IF(TODAY()>S6,"OVERDUE","Due in "&(S6-TODAY())&" days"))) | AF6: =IF(ISNUMBER(C6),IF(ISNUMBER(AE6),AE6-C6,TODAY()-C6),"")
O7: =IF(AND(N7="Yes",ISNUMBER(C7)),C7+30,"") | Q7: =IF(OR(N7<>"Yes",NOT(ISNUMBER(O7))),"",IF(ISNUMBER(P7),IF(P7<=O7,"On time","Late"),IF(TODAY()>O7,"OVERDUE","Due in "&(O7-TODAY())&" days"))) | U7: =IF(OR(R7<>"Yes",NOT(ISNUMBER(S7))),"",IF(ISNUMBER(T7),IF(T7<=S7,"On time","Late"),IF(TODAY()>S7,"OVERDUE","Due in "&(S7-TODAY())&" days"))) | AF7: =IF(ISNUMBER(C7),IF(ISNUMBER(AE7),AE7-C7,TODAY()-C7),"")
O8: =IF(AND(N8="Yes",ISNUMBER(C8)),C8+30,"") | Q8: =IF(OR(N8<>"Yes",NOT(ISNUMBER(O8))),"",IF(ISNUMBER(P8),IF(P8<=O8,"On time","Late"),IF(TODAY()>O8,"OVERDUE","Due in "&(O8-TODAY())&" days"))) | U8: =IF(OR(R8<>"Yes",NOT(ISNUMBER(S8))),"",IF(ISNUMBER(T8),IF(T8<=S8,"On time","Late"),IF(TODAY()>S8,"OVERDUE","Due in "&(S8-TODAY())&" days"))) | AF8: =IF(ISNUMBER(C8),IF(ISNUMBER(AE8),AE8-C8,TODAY()-C8),"")
O9: =IF(AND(N9="Yes",ISNUMBER(C9)),C9+30,"") | Q9: =IF(OR(N9<>"Yes",NOT(ISNUMBER(O9))),"",IF(ISNUMBER(P9),IF(P9<=O9,"On time","Late"),IF(TODAY()>O9,"OVERDUE","Due in "&(O9-TODAY())&" days"))) | U9: =IF(OR(R9<>"Yes",NOT(ISNUMBER(S9))),"",IF(ISNUMBER(T9),IF(T9<=S9,"On time","Late"),IF(TODAY()>S9,"OVERDUE","Due in "&(S9-TODAY())&" days"))) | AF9: =IF(ISNUMBER(C9),IF(ISNUMBER(AE9),AE9-C9,TODAY()-C9),"")
O10: =IF(AND(N10="Yes",ISNUMBER(C10)),C10+30,"") | Q10: =IF(OR(N10<>"Yes",NOT(ISNUMBER(O10))),"",IF(ISNUMBER(P10),IF(P10<=O10,"On time","Late"),IF(TODAY()>O10,"OVERDUE","Due in "&(O10-TODAY())&" days"))) | U10: =IF(OR(R10<>"Yes",NOT(ISNUMBER(S10))),"",IF(ISNUMBER(T10),IF(T10<=S10,"On time","Late"),IF(TODAY()>S10,"OVERDUE","Due in "&(S10-TODAY())&" days"))) | AF10: =IF(ISNUMBER(C10),IF(ISNUMBER(AE10),AE10-C10,TODAY()-C10),"")
O11: =IF(AND(N11="Yes",ISNUMBER(C11)),C11+30,"") | Q11: =IF(OR(N11<>"Yes",NOT(ISNUMBER(O11))),"",IF(ISNUMBER(P11),IF(P11<=O11,"On time","Late"),IF(TODAY()>O11,"OVERDUE","Due in "&(O11-TODAY())&" days"))) | U11: =IF(OR(R11<>"Yes",NOT(ISNUMBER(S11))),"",IF(ISNUMBER(T11),IF(T11<=S11,"On time","Late"),IF(TODAY()>S11,"OVERDUE","Due in "&(S11-TODAY())&" days"))) | AF11: =IF(ISNUMBER(C11),IF(ISNUMBER(AE11),AE11-C11,TODAY()-C11),"")
O12: =IF(AND(N12="Yes",ISNUMBER(C12)),C12+30,"") | Q12: =IF(OR(N12<>"Yes",NOT(ISNUMBER(O12))),"",IF(ISNUMBER(P12),IF(P12<=O12,"On time","Late"),IF(TODAY()>O12,"OVERDUE","Due in "&(O12-TODAY())&" days"))) | U12: =IF(OR(R12<>"Yes",NOT(ISNUMBER(S12))),"",IF(ISNUMBER(T12),IF(T12<=S12,"On time","Late"),IF(TODAY()>S12,"OVERDUE","Due in "&(S12-TODAY())&" days"))) | AF12: =IF(ISNUMBER(C12),IF(ISNUMBER(AE12),AE12-C12,TODAY()-C12),"")
O13: =IF(AND(N13="Yes",ISNUMBER(C13)),C13+30,"") | Q13: =IF(OR(N13<>"Yes",NOT(ISNUMBER(O13))),"",IF(ISNUMBER(P13),IF(P13<=O13,"On time","Late"),IF(TODAY()>O13,"OVERDUE","Due in "&(O13-TODAY())&" days"))) | U13: =IF(OR(R13<>"Yes",NOT(ISNUMBER(S13))),"",IF(ISNUMBER(T13),IF(T13<=S13,"On time","Late"),IF(TODAY()>S13,"OVERDUE","Due in "&(S13-TODAY())&" days"))) | AF13: =IF(ISNUMBER(C13),IF(ISNUMBER(AE13),AE13-C13,TODAY()-C13),"")
O14: =IF(AND(N14="Yes",ISNUMBER(C14)),C14+30,"") | Q14: =IF(OR(N14<>"Yes",NOT(ISNUMBER(O14))),"",IF(ISNUMBER(P14),IF(P14<=O14,"On time","Late"),IF(TODAY()>O14,"OVERDUE","Due in "&(O14-TODAY())&" days"))) | U14: =IF(OR(R14<>"Yes",NOT(ISNUMBER(S14))),"",IF(ISNUMBER(T14),IF(T14<=S14,"On time","Late"),IF(TODAY()>S14,"OVERDUE","Due in "&(S14-TODAY())&" days"))) | AF14: =IF(ISNUMBER(C14),IF(ISNUMBER(AE14),AE14-C14,TODAY()-C14),"")
O15: =IF(AND(N15="Yes",ISNUMBER(C15)),C15+30,"") | Q15: =IF(OR(N15<>"Yes",NOT(ISNUMBER(O15))),"",IF(ISNUMBER(P15),IF(P15<=O15,"On time","Late"),IF(TODAY()>O15,"OVERDUE","Due in "&(O15-TODAY())&" days"))) | U15: =IF(OR(R15<>"Yes",NOT(ISNUMBER(S15))),"",IF(ISNUMBER(T15),IF(T15<=S15,"On time","Late"),IF(TODAY()>S15,"OVERDUE","Due in "&(S15-TODAY())&" days"))) | AF15: =IF(ISNUMBER(C15),IF(ISNUMBER(AE15),AE15-C15,TODAY()-C15),"")
O16: =IF(AND(N16="Yes",ISNUMBER(C16)),C16+30,"") | Q16: =IF(OR(N16<>"Yes",NOT(ISNUMBER(O16))),"",IF(ISNUMBER(P16),IF(P16<=O16,"On time","Late"),IF(TODAY()>O16,"OVERDUE","Due in "&(O16-TODAY())&" days"))) | U16: =IF(OR(R16<>"Yes",NOT(ISNUMBER(S16))),"",IF(ISNUMBER(T16),IF(T16<=S16,"On time","Late"),IF(TODAY()>S16,"OVERDUE","Due in "&(S16-TODAY())&" days"))) | AF16: =IF(ISNUMBER(C16),IF(ISNUMBER(AE16),AE16-C16,TODAY()-C16),"")
O17: =IF(AND(N17="Yes",ISNUMBER(C17)),C17+30,"") | Q17: =IF(OR(N17<>"Yes",NOT(ISNUMBER(O17))),"",IF(ISNUMBER(P17),IF(P17<=O17,"On time","Late"),IF(TODAY()>O17,"OVERDUE","Due in "&(O17-TODAY())&" days"))) | U17: =IF(OR(R17<>"Yes",NOT(ISNUMBER(S17))),"",IF(ISNUMBER(T17),IF(T17<=S17,"On time","Late"),IF(TODAY()>S17,"OVERDUE","Due in "&(S17-TODAY())&" days"))) | AF17: =IF(ISNUMBER(C17),IF(ISNUMBER(AE17),AE17-C17,TODAY()-C17),"")
... O104: =IF(AND(N104="Yes",ISNUMBER(C104)),C104+30,"") | Q104: =IF(OR(N104<>"Yes",NOT(ISNUMBER(O104))),"",IF(ISNUMBER(P104),IF(P104<=O104,"On time","Late"),IF(TODAY()>O104,"OVERDUE","Due in "&(O104-TODAY())&" days"))) | U104: =IF(OR(R104<>"Yes",NOT(ISNUMBER(S104))),"",IF(ISNUMBER(T104),IF(T104<=S104,"On time","Late"),IF(TODAY()>S104,"OVERDUE","Due in "&(S104-TODAY())&" days"))) | AF104: =IF(ISNUMBER(C104),IF(ISNUMBER(AE104),AE104-C104,TODAY()-C104),"")

Sheet Dashboard
A1: Breach register dashboard
A2: Updates automatically from the Breach register tab. Uses today's date for overdue checks.
A4: Measure | B4: Count
A5: Breaches recorded | B5: =COUNTA('Breach register'!$A$5:$A$104) -> 1
A6: Open (not closed) | B6: =COUNTA('Breach register'!$A$5:$A$104)-COUNTIF('Breach register'!$AD$5:$AD$104,"Closed") -> 1
A7: Assessed as significant | B7: =COUNTIF('Breach register'!$L$5:$L$104,"Yes") -> 1
A8: Still under assessment | B8: =COUNTIF('Breach register'!$L$5:$L$104,"Under assessment") -> 0
A9: ASIC reports required | B9: =COUNTIF('Breach register'!$N$5:$N$104,"Yes") -> 1
A10: ASIC reports overdue (not yet lodged) | B10: =COUNTIF('Breach register'!$Q$5:$Q$104,"OVERDUE") -> 0
A11: ASIC reports lodged late | B11: =COUNTIF('Breach register'!$Q$5:$Q$104,"Late") -> 0
A12: APRA notifications overdue (not yet made) | B12: =COUNTIF('Breach register'!$U$5:$U$104,"OVERDUE") -> 0
A13: APRA notifications made late | B13: =COUNTIF('Breach register'!$U$5:$U$104,"Late") -> 0
A14: Customer remediation required | B14: =COUNTIF('Breach register'!$X$5:$X$104,"Yes") -> 1
A15: Customers / members affected (total) | B15: =SUM('Breach register'!$J$5:$J$104) -> 3000
A16: Estimated financial impact (total $) | B16: =SUM('Breach register'!$K$5:$K$104) -> 450000
A17: Average days open (open breaches) | B17: =IFERROR(AVERAGEIFS('Breach register'!$AF$5:$AF$104,'Breach register'!$AD$5:$AD$104,"<>Closed"),0) -> 26
A20: Breaches by source of obligation | B20: Count
A21: =Lists!$A$5 -> Corporations Act | B21: =COUNTIF('Breach register'!$G$5:$G$104,A21) -> 1
A22: =Lists!$A$6 -> SIS Act / Regulations | B22: =COUNTIF('Breach register'!$G$5:$G$104,A22) -> 0
A23: =Lists!$A$7 -> National Credit Act | B23: =COUNTIF('Breach register'!$G$5:$G$104,A23) -> 0
A24: =Lists!$A$8 -> ASIC Act | B24: =COUNTIF('Breach register'!$G$5:$G$104,A24) -> 0
A25: =Lists!$A$9 -> ASIC instrument or RG | B25: =COUNTIF('Breach register'!$G$5:$G$104,A25) -> 0
A26: =Lists!$A$10 -> APRA prudential standard | B26: =COUNTIF('Breach register'!$G$5:$G$104,A26) -> 0
A27: =Lists!$A$11 -> Privacy Act | B27: =COUNTIF('Breach register'!$G$5:$G$104,A27) -> 0
A28: =Lists!$A$12 -> AML/CTF Act | B28: =COUNTIF('Breach register'!$G$5:$G$104,A28) -> 0
A29: =Lists!$A$13 -> Industry code | B29: =COUNTIF('Breach register'!$G$5:$G$104,A29) -> 0
A30: =Lists!$A$14 -> Licence condition | B30: =COUNTIF('Breach register'!$G$5:$G$104,A30) -> 0
A31: =Lists!$A$15 -> Contract | B31: =COUNTIF('Breach register'!$G$5:$G$104,A31) -> 0
A32: =Lists!$A$16 -> Internal policy | B32: =COUNTIF('Breach register'!$G$5:$G$104,A32) -> 0
A33: =Lists!$A$17 -> Other | B33: =COUNTIF('Breach register'!$G$5:$G$104,A33) -> 0
A36: Breaches identified by month (last 12 months) | B36: Count
A37: =DATE(YEAR(TODAY()),MONTH(TODAY())-11,1) -> 45931 | B37: =COUNTIFS('Breach register'!$B$5:$B$104,">="&A37,'Breach register'!$B$5:$B$104,"<"&EDATE(A37,1)) -> 0
A38: =DATE(YEAR(TODAY()),MONTH(TODAY())-10,1) -> 45962 | B38: =COUNTIFS('Breach register'!$B$5:$B$104,">="&A38,'Breach register'!$B$5:$B$104,"<"&EDATE(A38,1)) -> 0
A39: =DATE(YEAR(TODAY()),MONTH(TODAY())-9,1) -> 45992 | B39: =COUNTIFS('Breach register'!$B$5:$B$104,">="&A39,'Breach register'!$B$5:$B$104,"<"&EDATE(A39,1)) -> 0
A40: =DATE(YEAR(TODAY()),MONTH(TODAY())-8,1) -> 46023 | B40: =COUNTIFS('Breach register'!$B$5:$B$104,">="&A40,'Breach register'!$B$5:$B$104,"<"&EDATE(A40,1)) -> 0
A41: =DATE(YEAR(TODAY()),MONTH(TODAY())-7,1) -> 46054 | B41: =COUNTIFS('Breach register'!$B$5:$B$104,">="&A41,'Breach register'!$B$5:$B$104,"<"&EDATE(A41,1)) -> 0
A42: =DATE(YEAR(TODAY()),MONTH(TODAY())-6,1) -> 46082 | B42: =COUNTIFS('Breach register'!$B$5:$B$104,">="&A42,'Breach register'!$B$5:$B$104,"<"&EDATE(A42,1)) -> 0
A43: =DATE(YEAR(TODAY()),MONTH(TODAY())-5,1) -> 46113 | B43: =COUNTIFS('Breach register'!$B$5:$B$104,">="&A43,'Breach register'!$B$5:$B$104,"<"&EDATE(A43,1)) -> 0
A44: =DATE(YEAR(TODAY()),MONTH(TODAY())-4,1) -> 46143 | B44: =COUNTIFS('Breach register'!$B$5:$B$104,">="&A44,'Breach register'!$B$5:$B$104,"<"&EDATE(A44,1)) -> 0
A45: =DATE(YEAR(TODAY()),MONTH(TODAY())-3,1) -> 46174 | B45: =COUNTIFS('Breach register'!$B$5:$B$104,">="&A45,'Breach register'!$B$5:$B$104,"<"&EDATE(A45,1)) -> 0
...
