Workbook

Sheet Read me
A1: Control testing workpaper
A2: RiskLens Australia · free template · version 1.0 (September 2026)
A4: What this is | B4: A workpaper for testing one control: the test plan, design assessment, sample results and conclusion, with reviewer sign-off. Background: https://hayesskvaril-ctrl.github.io/risk-management/control-design-and-testing.html and https://hayesskvaril-ctrl.github.io/risk-management/control-testing-sampling.html
A5: How to use it | B5: 1. Test plan: describe the control, the risk it addresses, the population and the attributes you will test (up to four). Record the design assessment. 2. Choose a sample size using your methodology (the 'Sample size guide' tab shows statistical sizes for attribute sampling). 3. Sample results: record each item tested and whether each attribute was met (Yes, No or N/A). Exceptions are flagged automatically. 4. Conclusion: review the exception count, exception rate and upper deviation limit, then record the operating effectiveness conclusion, findings and sign-offs.
A6: Worked example | B6: The yellow cells hold a fictional example: a four-eyes approval control over super benefit payments, with 25 items tested and one exception. Replace it with your own test.
A7: Upper deviation limit | B7: The Conclusion tab calculates how high the true exception rate could be, at the confidence level you choose, given what the sample found. It uses an exact binomial (Clopper-Pearson) upper bound and assumes a random sample from a large population. It's a statistical aid, not a substitute for judgement: one exception that reveals a design flaw or fraud matters more than the rate suggests.
A8: Colour key | B8: Pale yellow cells: fill these in (many have drop-down lists). Grey-blue cells: calculated automatically; don't type over them. Green rows: worked examples. Replace or delete them.
A9: Important | B9: RiskLens Australia provides general educational information only. It is not legal, financial or compliance advice and does not take into account your circumstances. Always refer to the official legislation and regulator guidance, and seek professional advice where appropriate.

Sheet Test plan
A1: Test plan and design assessment
A2: One workpaper per control. Fill in the yellow cells.
A4: About the control
A5: Workpaper reference | B5: CT-2026-07
A6: Control ID | B6: C-PAY-03
A7: Control description | B7: A second officer reviews and approves every benefit payment over $10,000 in the payment system before release, checking the payment against the member's claim form, identity verification and bank details.
A8: Control objective | B8: Benefit payments over $10,000 are valid, accurate and paid to the right member.
A9: Risk addressed | B9: Payment made to the wrong person or in the wrong amount (error or fraud).
A10: Control owner | B10: Payments Team Leader
A11: Frequency | B11: Multiple times a day
A12: Control type | B12: Preventive
A13: Manual or automated | B13: IT-dependent manual
A14: Key control? | B14: Yes
A15: Design assessment
A16: Does the design address the risk? (reasoning) | B16: Yes. The control operates before payment release, covers all payments over the threshold, and the system prevents the same user from creating and approving a payment.
A17: Design gaps identified | B17: Payments just under $10,000 are not reviewed; split-payment monitoring relies on a separate detective report.
A18: Design conclusion | B18: Effective
A19: Test approach
A20: Test period from | B20: 46023
A21: Test period to | B21: 46203
A22: Population description | B22: All benefit payments over $10,000 released between 1 January and 30 June 2026 (system report PAY-R12).
A23: Population size | B23: 4830
A24: How completeness of the population was checked | B24: Reconciled report total to the general ledger benefit payments account for the period.
A25: Test method | B25: Reperformance
A26: Sampling method | B26: Random selection using a random number generator over the report row numbers.
A27: Planned sample size | B27: 25
A28: Basis for sample size | B28: Methodology table for controls operating multiple times a day. See the Sample size guide tab for the confidence this implies.
A29: Attribute A | B29: Approver is a different person from the payment creator.
A30: Attribute B | B30: Payment amount agrees to the claim form and benefit calculation.
A31: Attribute C | B31: Bank details agree to verified member records.
A32: Attribute D | B32: Approval evidenced in the system before payment release.
A33: Tester | B33: Operational Risk Analyst
A34: Date testing completed | B34: 46227

Sheet Sample results
A1: Sample results
A2: One row per item tested. Record Yes (met), No (not met) or N/A for each attribute.
A4: # | B4: Item reference | C4: Item date | D4: Attribute A | E4: Attribute B | F4: Attribute C | G4: Attribute D | H4: Exception? | I4: Exception description | J4: Evidence reference | K4: Tester notes
A5: Tests: | D5: ='Test plan'!B29 -> Approver is a different person from the payment creator. | E5: ='Test plan'!B30 -> Payment amount agrees to the claim form and benefit calculation. | F5: ='Test plan'!B31 -> Bank details agree to verified member records. | G5: ='Test plan'!B32 -> Approval evidenced in the system before payment release.
A6: 1 | B6: PAY-260173 | C6: 46025 | D6: Yes | E6: Yes | F6: Yes | G6: Yes | H6: =IF(COUNTA(D6:G6)=0,"",IF(COUNTIF(D6:G6,"No")>0,"Yes","No")) -> No | J6: Screenshot folder CT-2026-07/01
A7: 2 | B7: PAY-260346 | C7: 46030 | D7: Yes | E7: Yes | F7: Yes | G7: Yes | H7: =IF(COUNTA(D7:G7)=0,"",IF(COUNTIF(D7:G7,"No")>0,"Yes","No")) -> No | J7: Screenshot folder CT-2026-07/02
A8: 3 | B8: PAY-260519 | C8: 46035 | D8: Yes | E8: Yes | F8: Yes | G8: Yes | H8: =IF(COUNTA(D8:G8)=0,"",IF(COUNTIF(D8:G8,"No")>0,"Yes","No")) -> No | J8: Screenshot folder CT-2026-07/03
A9: 4 | B9: PAY-260692 | C9: 46040 | D9: Yes | E9: Yes | F9: Yes | G9: Yes | H9: =IF(COUNTA(D9:G9)=0,"",IF(COUNTIF(D9:G9,"No")>0,"Yes","No")) -> No | J9: Screenshot folder CT-2026-07/04
A10: 5 | B10: PAY-260865 | C10: 46045 | D10: Yes | E10: Yes | F10: Yes | G10: Yes | H10: =IF(COUNTA(D10:G10)=0,"",IF(COUNTIF(D10:G10,"No")>0,"Yes","No")) -> No | J10: Screenshot folder CT-2026-07/05
A11: 6 | B11: PAY-261038 | C11: 46056 | D11: Yes | E11: Yes | F11: Yes | G11: Yes | H11: =IF(COUNTA(D11:G11)=0,"",IF(COUNTIF(D11:G11,"No")>0,"Yes","No")) -> No | J11: Screenshot folder CT-2026-07/06
A12: 7 | B12: PAY-261211 | C12: 46061 | D12: Yes | E12: Yes | F12: Yes | G12: Yes | H12: =IF(COUNTA(D12:G12)=0,"",IF(COUNTIF(D12:G12,"No")>0,"Yes","No")) -> No | J12: Screenshot folder CT-2026-07/07
A13: 8 | B13: PAY-261384 | C13: 46066 | D13: Yes | E13: Yes | F13: Yes | G13: Yes | H13: =IF(COUNTA(D13:G13)=0,"",IF(COUNTIF(D13:G13,"No")>0,"Yes","No")) -> No | J13: Screenshot folder CT-2026-07/08
A14: 9 | B14: PAY-261557 | C14: 46071 | D14: Yes | E14: Yes | F14: Yes | G14: Yes | H14: =IF(COUNTA(D14:G14)=0,"",IF(COUNTIF(D14:G14,"No")>0,"Yes","No")) -> No | J14: Screenshot folder CT-2026-07/09
A15: 10 | B15: PAY-261730 | C15: 46076 | D15: Yes | E15: Yes | F15: Yes | G15: Yes | H15: =IF(COUNTA(D15:G15)=0,"",IF(COUNTIF(D15:G15,"No")>0,"Yes","No")) -> No | J15: Screenshot folder CT-2026-07/10
A16: 11 | B16: PAY-261903 | C16: 46084 | D16: Yes | E16: Yes | F16: Yes | G16: Yes | H16: =IF(COUNTA(D16:G16)=0,"",IF(COUNTIF(D16:G16,"No")>0,"Yes","No")) -> No | J16: Screenshot folder CT-2026-07/11
A17: 12 | B17: PAY-262076 | C17: 46089 | D17: Yes | E17: Yes | F17: Yes | G17: Yes | H17: =IF(COUNTA(D17:G17)=0,"",IF(COUNTIF(D17:G17,"No")>0,"Yes","No")) -> No | J17: Screenshot folder CT-2026-07/12
A18: 13 | B18: PAY-262249 | C18: 46094 | D18: Yes | E18: Yes | F18: Yes | G18: Yes | H18: =IF(COUNTA(D18:G18)=0,"",IF(COUNTIF(D18:G18,"No")>0,"Yes","No")) -> No | J18: Screenshot folder CT-2026-07/13
A19: 14 | B19: PAY-262422 | C19: 46099 | D19: Yes | E19: Yes | F19: Yes | G19: No | H19: =IF(COUNTA(D19:G19)=0,"",IF(COUNTIF(D19:G19,"No")>0,"Yes","No")) -> Yes | I19: Approval recorded 40 minutes after payment release. Payment was valid, but the control did not operate before release. | J19: Screenshot folder CT-2026-07/14 | K19: Confirmed with Payments Team Leader: a system override was used during an outage. Override log reviewed.
A20: 15 | B20: PAY-262595 | C20: 46104 | D20: Yes | E20: Yes | F20: Yes | G20: Yes | H20: =IF(COUNTA(D20:G20)=0,"",IF(COUNTIF(D20:G20,"No")>0,"Yes","No")) -> No | J20: Screenshot folder CT-2026-07/15
A21: 16 | B21: PAY-262768 | C21: 46115 | D21: Yes | E21: Yes | F21: Yes | G21: Yes | H21: =IF(COUNTA(D21:G21)=0,"",IF(COUNTIF(D21:G21,"No")>0,"Yes","No")) -> No | J21: Screenshot folder CT-2026-07/16
A22: 17 | B22: PAY-262941 | C22: 46120 | D22: Yes | E22: Yes | F22: Yes | G22: Yes | H22: =IF(COUNTA(D22:G22)=0,"",IF(COUNTIF(D22:G22,"No")>0,"Yes","No")) -> No | J22: Screenshot folder CT-2026-07/17
A23: 18 | B23: PAY-263114 | C23: 46125 | D23: Yes | E23: Yes | F23: Yes | G23: Yes | H23: =IF(COUNTA(D23:G23)=0,"",IF(COUNTIF(D23:G23,"No")>0,"Yes","No")) -> No | J23: Screenshot folder CT-2026-07/18
A24: 19 | B24: PAY-263287 | C24: 46130 | D24: Yes | E24: Yes | F24: Yes | G24: Yes | H24: =IF(COUNTA(D24:G24)=0,"",IF(COUNTIF(D24:G24,"No")>0,"Yes","No")) -> No | J24: Screenshot folder CT-2026-07/19
A25: 20 | B25: PAY-263460 | C25: 46135 | D25: Yes | E25: Yes | F25: Yes | G25: Yes | H25: =IF(COUNTA(D25:G25)=0,"",IF(COUNTIF(D25:G25,"No")>0,"Yes","No")) -> No | J25: Screenshot folder CT-2026-07/20
A26: 21 | B26: PAY-263633 | C26: 46145 | D26: Yes | E26: Yes | F26: Yes | G26: Yes | H26: =IF(COUNTA(D26:G26)=0,"",IF(COUNTIF(D26:G26,"No")>0,"Yes","No")) -> No | J26: Screenshot folder CT-2026-07/21
A27: 22 | B27: PAY-263806 | C27: 46150 | D27: Yes | E27: Yes | F27: Yes | G27: Yes | H27: =IF(COUNTA(D27:G27)=0,"",IF(COUNTIF(D27:G27,"No")>0,"Yes","No")) -> No | J27: Screenshot folder CT-2026-07/22
A28: 23 | B28: PAY-263979 | C28: 46155 | D28: Yes | E28: Yes | F28: Yes | G28: Yes | H28: =IF(COUNTA(D28:G28)=0,"",IF(COUNTIF(D28:G28,"No")>0,"Yes","No")) -> No | J28: Screenshot folder CT-2026-07/23
A29: 24 | B29: PAY-264152 | C29: 46160 | D29: Yes | E29: Yes | F29: Yes | G29: Yes | H29: =IF(COUNTA(D29:G29)=0,"",IF(COUNTIF(D29:G29,"No")>0,"Yes","No")) -> No | J29: Screenshot folder CT-2026-07/24
A30: 25 | B30: PAY-264325 | C30: 46165 | D30: Yes | E30: Yes | F30: Yes | G30: Yes | H30: =IF(COUNTA(D30:G30)=0,"",IF(COUNTIF(D30:G30,"No")>0,"Yes","No")) -> No | J30: Screenshot folder CT-2026-07/25
A31: 26 | H31: =IF(COUNTA(D31:G31)=0,"",IF(COUNTIF(D31:G31,"No")>0,"Yes","No"))
A32: 27 | H32: =IF(COUNTA(D32:G32)=0,"",IF(COUNTIF(D32:G32,"No")>0,"Yes","No"))
A33: 28 | H33: =IF(COUNTA(D33:G33)=0,"",IF(COUNTIF(D33:G33,"No")>0,"Yes","No"))
A34: 29 | H34: =IF(COUNTA(D34:G34)=0,"",IF(COUNTIF(D34:G34,"No")>0,"Yes","No"))
A35: 30 | H35: =IF(COUNTA(D35:G35)=0,"",IF(COUNTIF(D35:G35,"No")>0,"Yes","No"))
A36: 31 | H36: =IF(COUNTA(D36:G36)=0,"",IF(COUNTIF(D36:G36,"No")>0,"Yes","No"))
A37: 32 | H37: =IF(COUNTA(D37:G37)=0,"",IF(COUNTIF(D37:G37,"No")>0,"Yes","No"))
A38: 33 | H38: =IF(COUNTA(D38:G38)=0,"",IF(COUNTIF(D38:G38,"No")>0,"Yes","No"))
A39: 34 | H39: =IF(COUNTA(D39:G39)=0,"",IF(COUNTIF(D39:G39,"No")>0,"Yes","No"))
A40: 35 | H40: =IF(COUNTA(D40:G40)=0,"",IF(COUNTIF(D40:G40,"No")>0,"Yes","No"))
A41: 36 | H41: =IF(COUNTA(D41:G41)=0,"",IF(COUNTIF(D41:G41,"No")>0,"Yes","No"))
...

Sheet Conclusion
A1: Results and conclusion
A2: Calculated results update from the Sample results tab. Fill in the yellow cells.
A4: Results
A5: Items tested | B5: =COUNTIF('Sample results'!H6:H65,"Yes")+COUNTIF('Sample results'!H6:H65,"No") -> 25
A6: Planned sample size | B6: ='Test plan'!B27 -> 25
A7: Exceptions (items with at least one 'No') | B7: =COUNTIF('Sample results'!H6:H65,"Yes") -> 1
A8: Exception rate in the sample | B8: =IF(B5=0,"",B7/B5) -> 0.04
A9: Exceptions by attribute (A / B / C / D) | B9: =COUNTIF('Sample results'!D6:D65,"No")&" / "&COUNTIF('Sample results'!E6:E65,"No")&" / "&COUNTIF('Sample results'!F6:F65,"No")&" / "&COUNTIF('Sample results'!G6:G65,"No") -> 0 / 0 / 0 / 1
A10: Statistical check (optional)
A11: Confidence level | B11: 0.95
A12: Tolerable exception rate | B12: 0.1
A13: Upper deviation limit | B13: =IF(B5=0,"",IF(B7>=B5,1,BETAINV(B11,B7+1,B5-B7))) -> 0.17612071
A14: Statistical result | B14: =IF(B13="","",IF(B13<=B12,"Supports reliance: upper limit is within the tolerable rate","Does not support reliance: upper limit exceeds the tolerable rate")) -> Does not support reliance: upper limit exceeds the tolerable rate
A15: Sample complete? | B15: =IF(B5=0,"",IF(B5>=B6,"Yes","No: "&(B6-B5)&" items still to test")) -> Yes
A16: Conclusion
A17: Root cause of exceptions | B17: A system override used during a payment platform outage let a payment release before approval. Override use was not reviewed after the event.
A18: Is an exception isolated or systemic? (reasoning) | B18: Isolated to one outage day, but the override process is a design gap: it could recur in any outage.
A19: Operating effectiveness conclusion | B19: Partially effective
A20: Overall control rating | B20: Partially effective
A21: Findings and agreed actions | B21: 1. Require retrospective approval and second-line review of every override (owner: Payments Team Leader, due 30/09/2026). 2. Add override use to the monthly payments KRI report.
A22: Issue raised in issues register? | B22: Yes
A23: Sign-off
A24: Prepared by | B24: Operational Risk Analyst
A25: Date prepared | B25: 46227
A26: Reviewed by | B26: Operational Risk Manager
A27: Date reviewed | B27: 46232
A28: Reviewer comments | B28: Agree with conclusion. Confirm override review is added to the control description once implemented.

Sheet Sample size guide
A1: Sample size guide (attribute sampling)
A2: Minimum sample sizes for a large population, from the binomial distribution.
A4: Confidence | B4: Tolerable exception rate | C4: 0 exceptions allowed | D4: 1 exception allowed | E4: 2 exceptions allowed
A5: 0.8 | B5: 0.05 | C5: 32 | D5: 59 | E5: 85
A6: 0.8 | B6: 0.1 | C6: 16 | D6: 29 | E6: 42
A7: 0.8 | B7: 0.15 | C7: 10 | D7: 19 | E7: 28
A8: 0.8 | B8: 0.2 | C8: 8 | D8: 14 | E8: 21
A9: 0.9 | B9: 0.05 | C9: 45 | D9: 77 | E9: 105
A10: 0.9 | B10: 0.1 | C10: 22 | D10: 38 | E10: 52
A11: 0.9 | B11: 0.15 | C11: 15 | D11: 25 | E11: 34
A12: 0.9 | B12: 0.2 | C12: 11 | D12: 18 | E12: 25
A13: 0.95 | B13: 0.05 | C13: 59 | D13: 93 | E13: 124
A14: 0.95 | B14: 0.1 | C14: 29 | D14: 46 | E14: 61
A15: 0.95 | B15: 0.15 | C15: 19 | D15: 30 | E15: 40
A16: 0.95 | B16: 0.2 | C16: 14 | D16: 22 | E16: 30
A18: How to read it: to be 95% confident the true exception rate is no more than 10%, test 29 items and find no exceptions, or 46 items and find no more than one.
A19: These sizes assume a random sample from a large population. For small populations (e.g. a quarterly control with four occurrences), many testers test all or most occurrences instead.
A20: Many organisations set sample sizes by control frequency in their testing methodology. Those tables are practical; this guide helps show the level of confidence they imply.
A21: More explanation and an interactive calculator: https://hayesskvaril-ctrl.github.io/risk-management/control-testing-sampling.html

Sheet Lists
A1: Drop-down lists
A2: Edit these values to suit your organisation. The drop-downs read from this tab.
A4: Frequency | B4: Control type | C4: Manual or automated | D4: Test method | E4: Design | F4: Result | G4: Conclusion | H4: Confidence | I4: Yes / No
A5: Multiple times a day | B5: Preventive | C5: Manual | D5: Inquiry only | E5: Effective | F5: Yes | G5: Effective | H5: 0.8 | I5: Yes
A6: Daily | B6: Detective | C6: IT-dependent manual | D6: Inquiry and observation | E6: Partially effective | F6: No | G6: Partially effective | H6: 0.9 | I6: No
A7: Weekly | B7: Corrective | C7: Automated | D7: Inspection of evidence | E7: Ineffective | F7: N/A | G7: Ineffective | H7: 0.95
A8: Monthly | D8: Reperformance | G8: Unable to conclude | H8: 0.99
A9: Quarterly | D9: Combination
A10: Annually
A11: Event-driven
